Traceback (most recent call last):
  File "/home/jplal/miniforge3/envs/mcgt-dev/lib/python3.12/site-packages/pandas/core/indexes/base.py", line 3812, in get_loc
    return self._engine.get_loc(casted_key)
           ^^^^^^^^^^^^^^^^^^^^^^^^^^^^^^^^
  File "pandas/_libs/index.pyx", line 167, in pandas._libs.index.IndexEngine.get_loc
  File "pandas/_libs/index.pyx", line 196, in pandas._libs.index.IndexEngine.get_loc
  File "pandas/_libs/hashtable_class_helper.pxi", line 7088, in pandas._libs.hashtable.PyObjectHashTable.get_item
  File "pandas/_libs/hashtable_class_helper.pxi", line 7096, in pandas._libs.hashtable.PyObjectHashTable.get_item
KeyError: 'T'

The above exception was the direct cause of the following exception:

Traceback (most recent call last):
  File "/home/jplal/MCGT/zz-scripts/chapter01/plot_fig06_P_derivative_comparison.py", line 13, in <module>
    T_i, dP_i = df_init[ "T"], df_init[ "dP_dT"]
                ~~~~~~~^^^^^^
  File "/home/jplal/miniforge3/envs/mcgt-dev/lib/python3.12/site-packages/pandas/core/frame.py", line 4107, in __getitem__
    indexer = self.columns.get_loc(key)
              ^^^^^^^^^^^^^^^^^^^^^^^^^
  File "/home/jplal/miniforge3/envs/mcgt-dev/lib/python3.12/site-packages/pandas/core/indexes/base.py", line 3819, in get_loc
    raise KeyError(key) from err
KeyError: 'T'
